Workbook

Sheet 统计
A1: 42690
A2: 部分基因编码错误纠正
A3: 1、以前方案为根据rs纠正
A4: 2、初步估计有1337条mRNA存在明显编码问题，共774个基因(有些基因与mRNA的名称一致，但位置不一致)，存在问题较大的变体307个（基因208个）
A5: 总mRNA | B5: 存在错误mRNA | C5: cds为3的倍数（AA=1） | D5: cds为3的倍数（AA=2） | E5: cds为3的倍数（AA=3） | F5: cds为3的倍数（AA=4） | G5: cds为3的倍数（AA=5） | H5: cds为3的倍数（AA=6） | I5: cds为3的倍数（AA=7） | J5: cds为3的倍数（AA=8） | K5: cds为3的倍数（AA=9） | L5: cds为3的倍数（AA=10） | M5: cds为3的倍数（AA>10） | N5: cds不为3的倍数（AA<=10） | O5: cds不为3的倍数（AA>10）
A6: 34042 | B6: 1337（774） | C6: 915（517） | D6: 79（48） | E6: 8（3） | F6: 2（2） | G6: 2（2,同基因名XY） | H6: 5（2，DPP6有两个位置3个mRNA） | I6: 0 | J6: 0 | K6: 2（1） | L6: 6（2,INPP5D有两个位置2个mRNA） | M6: 72（54） | N6: 11（7, 含1个编码正确） | O6: 235（154）
A7: 第一次修正数目 | G7: 2(1) | H7: 2(1,DPP6) | K7: 2(1) | L7: 4(1) | M7: 43(31) | N7: 2(1) | O7: 161(109)
A8: 第二次修正数目 | M8: 14(10) | O8: 10(9)
A9: 第三次修正数目
A10: 基因分为多段(暂不解决) | H10: 1(1,DPP6) | L10: 2(1) | M10: 5(3) | N10: 1(1,编码正确) | O10: 28（8）
A11: 基因不完整(CDS起始终止变化) | M11: 7(6) | N11: 3(2) | O11: 16(14)
A12: 变体或基因被取消、假基因 | M12: 1（1） | N12: 3（1） | O12: 14（14）
A13: 未解决 | M13: 2（1） | N13: 2（1） | O13: 6（3）
A14: 3、优先解决上表中后三列中的错误mRNA，前面这些很可能为碱基错误造成
A15: 4、部分mRNA因基因组组装问题可能无法解决 | G15: =517+48+3+4 -> 572
A16: 5、部分UTR区错误，不影响编码，暂时不解决
A18: 解决方案：
A19: 可分三大类：相对基因组存在小的INDEL、外显子（CDS）变化、外显子（CDS）变化+相对基因组存在小的INDEL | L19: 2 | M19: 14
L20: 2 | M20: 15
A21: 第一类：相对基因组存在INDEL,且编码起始位置无变化 | L21: 1 | M21: 22
A22: 1、通过blat比对结果（NCBI knownrefseq_alignments.gff3）可找出这些INDEL | L22: 1 | M22: 29
A23: 2、通过INDEL的位置对造成错误的编码进行修正 | L23: 2 | M23: 33
A24: 3、出现INDEL的位置，通过MeMAF进行碱基修正，如基因组缺少一个碱基，则通过MeMAF补全这个碱基，再进行编码 | L24: 1 | M24: 63
A25: 4、注释的突变正好为INDEL位置则给予同义突变或非移码，并给标记（Normal） | L25: 1 | M25: 68
A26: 5、在INDEL附近位置突变，氨基酸变化可能不正确
A27: 6、该变体上的INDEL移码、提前终止、延长突变，氨基酸变化数目可能不正确
L28: 1 | M28: 75
A29: 第二类：外显子（CDS）变化 | L29: 1 | M29: 79
A30: 1、修正外显子（CDS）区间 | L30: 1 | M30: 80
L31: 2 | M31: 82
L32: 1 | M32: 93
A33: 第三类：外显子（CDS）变化+相对基因组存在小的INDEL | L33: 1 | M33: 102
A34: 1、结合第一类与第二类 | L34: 1 | M34: 126
L35: 1 | M35: 155
L36: 1 | M36: 180
L37: 2 | M37: 183
L38: 1 | M38: 184
L39: 1 | M39: 197
L40: 1 | M40: 208
L41: 1 | M41: 216
...

Sheet 错误mRNA总表
A1: mRNA | B1: chr | C1: start | D1: combin | E1: gene | F1: wrongAA | G1: 备注 | H1: 第一次纠正情况 | I1: 第二次纠正情况 | J1: 是否存在纠错信息
A2: NM_000014 | B2: chr12 | C2: 9220303 | D2: NM_000014chr12:9220304 | E2: A2M | F2: 1 | J2: =IF(H2="",IF(I2="","",I2),H2)
A3: NM_000024 | B3: chr5 | C3: 148206155 | D3: NM_000024chr5:148206156 | E3: ADRB2 | F3: 2 | J3: =IF(H3="",IF(I3="","",I3),H3)
A4: NM_000051 | B4: chr11 | C4: 108093558 | D4: NM_000051chr11:108093559 | E4: ATM | F4: 1 | J4: =IF(H4="",IF(I4="","",I4),H4)
A5: NM_000059 | B5: chr13 | C5: 32889616 | D5: NM_000059chr13:32889617 | E5: BRCA2 | F5: 1 | J5: =IF(H5="",IF(I5="","",I5),H5)
A6: NM_000083 | B6: chr7 | C6: 143013218 | D6: NM_000083chr7:143013219 | E6: CLCN1 | F6: 1 | J6: =IF(H6="",IF(I6="","",I6),H6)
A7: NM_000088 | B7: chr17 | C7: 48261456 | D7: NM_000088chr17:48261457 | E7: COL1A1 | F7: 1 | J7: =IF(H7="",IF(I7="","",I7),H7)
A8: NM_000090 | B8: chr2 | C8: 189839098 | D8: NM_000090chr2:189839099 | E8: COL3A1 | F8: 1 | J8: =IF(H8="",IF(I8="","",I8),H8)
A9: NM_000096 | B9: chr3 | C9: 148890285 | D9: NM_000096chr3:148890286 | E9: CP | F9: 1 | J9: =IF(H9="",IF(I9="","",I9),H9)
A10: NM_000104 | B10: chr2 | C10: 38294745 | D10: NM_000104chr2:38294746 | E10: CYP1B1 | F10: 1 | J10: =IF(H10="",IF(I10="","",I10),H10)
A11: NM_000106 | B11: chr22 | C11: 42522500 | D11: NM_000106chr22:42522501 | E11: CYP2D6 | F11: 2 | J11: =IF(H11="",IF(I11="","",I11),H11)
A12: NM_000109 | B12: chrX | C12: 31137344 | D12: NM_000109chrX:31137345 | E12: DMD | F12: 3 | J12: =IF(H12="",IF(I12="","",I12),H12)
A13: NM_000110 | B13: chr1 | C13: 97543298 | D13: NM_000110chr1:97543299 | E13: DPYD | F13: 1 | J13: =IF(H13="",IF(I13="","",I13),H13)
... A23: NM_000259 | B23: chr15 | C23: 52599479 | D23: NM_000259chr15:52599480 | E23: MYO5A | F23: 1 | J23: =IF(H23="",IF(I23="","",I23),H23)
A24: NM_000278 | B24: chr10 | C24: 102505467 | D24: NM_000278chr10:102505468 | E24: PAX2 | F24: 9 | H24: 纠后正确，少1个氨基酸chr10:102587349-102587376 | J24: =IF(H24="",IF(I24="","",I24),H24) -> 纠后正确，少1个氨基酸chr10:102587349-102587376
A25: NM_000283 | B25: chr4 | C25: 619362 | D25: NM_000283chr4:619363 | E25: PDE6B | F25: 1 | J25: =IF(H25="",IF(I25="","",I25),H25)
A26: NM_000296 | B26: chr16 | C26: 2138710 | D26: NM_000296chr16:2138711 | E26: PKD1 | F26: 1 | J26: =IF(H26="",IF(I26="","",I26),H26)
A27: NM_000318 | B27: chr8 | C27: 77892493 | D27: NM_000318chr8:77892494 | E27: PEX2 | F27: 1 | J27: =IF(H27="",IF(I27="","",I27),H27)
A28: NM_000327 | B28: chr11 | C28: 62380212 | D28: NM_000327chr11:62380213 | E28: ROM1 | F28: 1 | J28: =IF(H28="",IF(I28="","",I28),H28)
A29: NM_000331 | B29: chr11 | C29: 18287807 | D29: NM_000331chr11:18287808 | E29: SAA1 | F29: 1 | J29: =IF(H29="",IF(I29="","",I29),H29)
A30: NM_000339 | B30: chr16 | C30: 56899118 | D30: NM_000339chr16:56899119 | E30: SLC12A3 | F30: 1 | J30: =IF(H30="",IF(I30="","",I30),H30)
A31: NM_000348 | B31: chr2 | C31: 31749655 | D31: NM_000348chr2:31749656 | E31: SRD5A2 | F31: CDS3_10 | H31: 纠后正确 | J31: =IF(H31="",IF(I31="","",I31),H31) -> 纠后正确
A32: NM_000378 | B32: chr11 | C32: 32409320 | D32: NM_000378chr11:32409321 | E32: WT1 | F32: 1 | J32: =IF(H32="",IF(I32="","",I32),H32)
A33: NM_000384 | B33: chr2 | C33: 21224300 | D33: NM_000384chr2:21224301 | E33: APOB | F33: 2 | J33: =IF(H33="",IF(I33="","",I33),H33)
A34: NM_000388 | B34: chr3 | C34: 121902529 | D34: NM_000388chr3:121902530 | E34: CASR | F34: 1 | J34: =IF(H34="",IF(I34="","",I34),H34)
A35: NM_000392 | B35: chr10 | C35: 101542462 | D35: NM_000392chr10:101542463 | E35: ABCC2 | F35: 1 | J35: =IF(H35="",IF(I35="","",I35),H35)
A36: NM_000404 | B36: chr3 | C36: 33038099 | D36: NM_000404chr3:33038100 | E36: GLB1 | F36: 1 | J36: =IF(H36="",IF(I36="","",I36),H36)
A37: NM_000421 | B37: chr17 | C37: 38974368 | D37: NM_000421chr17:38974369 | E37: KRT10 | F37: 1 | J37: =IF(H37="",IF(I37="","",I37),H37)
A38: NM_000426 | B38: chr6 | C38: 129204285 | D38: NM_000426chr6:129204286 | E38: LAMA2 | F38: 1 | J38: =IF(H38="",IF(I38="","",I38),H38)
A39: NM_000442 | B39: chr17 | C39: 62396774 | D39: NM_000442chr17:62396775 | E39: PECAM1 | F39: >=11 | G39: 基因不完整 | H39: 错误 | J39: =IF(H39="",IF(I39="","",I39),H39) -> 错误
A40: NM_000448 | B40: chr11 | C40: 36589562 | D40: NM_000448chr11:36589563 | E40: RAG1 | F40: 1 | J40: =IF(H40="",IF(I40="","",I40),H40)
A41: NM_000452 | B41: chr13 | C41: 103696347 | D41: NM_000452chr13:103696348 | E41: SLC10A2 | F41: 1 | J41: =IF(H41="",IF(I41="","",I41),H41)
A42: NM_000459 | B42: chr9 | C42: 27109146 | D42: NM_000459chr9:27109147 | E42: TEK | F42: 1 | J42: =IF(H42="",IF(I42="","",I42),H42)
A43: NM_000479 | B43: chr19 | C43: 2249112 | D43: NM_000479chr19:2249113 | E43: AMH | F43: 1 | J43: =IF(H43="",IF(I43="","",I43),H43)
A44: NM_000521 | B44: chr5 | C44: 73980968 | D44: NM_000521chr5:73980969 | E44: HEXB | F44: 1 | J44: =IF(H44="",IF(I44="","",I44),H44)
A45: NM_000526 | B45: chr17 | C45: 39738530 | D45: NM_000526chr17:39738531 | E45: KRT14 | F45: 1 | J45: =IF(H45="",IF(I45="","",I45),H45)
A46: NM_000535 | B46: chr7 | C46: 6012869 | D46: NM_000535chr7:6012870 | E46: PMS2 | F46: 1 | J46: =IF(H46="",IF(I46="","",I46),H46)
A47: NM_000544 | B47: chr6 | C47: 32793186 | D47: NM_000544chr6:32793187 | E47: TAP2 | F47: 2 | J47: =IF(H47="",IF(I47="","",I47),H47)
A48: NM_000545 | B48: chr12 | C48: 121416548 | D48: NM_000545chr12:121416549 | E48: HNF1A | F48: 1 | J48: =IF(H48="",IF(I48="","",I48),H48)
A49: NM_000552 | B49: chr12 | C49: 6058039 | D49: NM_000552chr12:6058040 | E49: VWF | F49: 1 | J49: =IF(H49="",IF(I49="","",I49),H49)
...

Sheet INDEL位置信息
A1: #mRNA | B1: Chr(NCBI) | C1: Start | D1: IndelPos(0) | E1: type | F1: Length | G1: Chr | H1: mRNA_NoVersion | I1: combin | J1: 变体是否需要纠错 | K1: 是否存在纠正信息 | L1: 第一次纠后信息 | M1: 第二次纠后信息
A2: NR_110830.1 | B2: NC_000023.10 | C2: 1314869 | D2: 1314883 | E2: INS | F2: 2 | G2: chrX | H2: NR_110830 | I2: NR_110830chrX:1314869 | M2: =VLOOKUP(I2,错误mRNA总表!D:I,6,FALSE) -> #N/A
A3: NR_110830.1 | B3: NC_000023.10 | C3: 1314869 | D3: 1314893 | E3: INS | F3: 1 | G3: chrX | H3: NR_110830 | I3: NR_110830chrX:1314869 | M3: =VLOOKUP(I3,错误mRNA总表!D:I,6,FALSE) -> #N/A
A4: NM_001346050.1 | B4: NC_000005.9 | C4: 180682147 | D4: 180682608 | E4: DEL | F4: 1 | G4: chr5 | H4: NM_001346050 | I4: NM_001346050chr5:180682147 | M4: =VLOOKUP(I4,错误mRNA总表!D:I,6,FALSE) -> #N/A
A5: NM_001001419.1 | B5: NC_000005.9 | C5: 135468536 | D5: 135513085 | E5: INS | F5: 1 | G5: chr5 | H5: NM_001001419 | I5: NM_001001419chr5:135468536 | J5: NM_001001419chr5:135468536 | K5: =VLOOKUP(J5,错误mRNA总表!D:J,7,FALSE) -> 纠后正确 | L5: 纠后正确 | M5: =VLOOKUP(I5,错误mRNA总表!D:I,6,FALSE) -> 0
A6: NM_031945.4 | B6: NC_000017.10 | C6: 79609331 | D6: 79614937 | E6: DEL | F6: 4 | G6: chr17 | H6: NM_031945 | I6: NM_031945chr17:79609331 | J6: NM_031945chr17:79609349 | K6: =VLOOKUP(J6,错误mRNA总表!D:J,7,FALSE) -> 纠后正确 | M6: =VLOOKUP(I6,错误mRNA总表!D:I,6,FALSE) -> #N/A
A7: NM_173681.5 | B7: NC_000007.13 | C7: 150709297 | D7: 150713902 | E7: INS | F7: 1 | G7: chr7 | H7: NM_173681 | I7: NM_173681chr7:150709297 | J7: NM_173681chr7:150709297 | K7: =VLOOKUP(J7,错误mRNA总表!D:J,7,FALSE) -> 纠后正确 | L7: 纠后正确 | M7: =VLOOKUP(I7,错误mRNA总表!D:I,6,FALSE) -> 0
A8: NM_021250.3 | B8: NW_003571054.1 | C8: 288498 | D8: 288670 | E8: DEL | F8: 2 | G8: NW_003571054.1 | H8: NM_021250 | I8: NM_021250:288498 | M8: =VLOOKUP(I8,错误mRNA总表!D:I,6,FALSE) -> #N/A
A9: NM_001145303.1 | B9: NW_003571060.1 | C9: 134946 | D9: 147897 | E9: DEL | F9: 1 | G9: NW_003571060.1 | H9: NM_001145303 | I9: NM_001145303:134946 | M9: =VLOOKUP(I9,错误mRNA总表!D:I,6,FALSE) -> #N/A
A10: NM_001290049.1 | B10: NC_000004.11 | C10: 76649706 | D10: 76650069 | E10: INS | F10: 23 | G10: chr4 | H10: NM_001290049 | I10: NM_001290049chr4:76649706 | M10: =VLOOKUP(I10,错误mRNA总表!D:I,6,FALSE) -> #N/A
A11: NM_001290049.1 | B11: NC_000004.11 | C11: 76649706 | D11: 76657500 | E11: INS | F11: 96 | G11: chr4 | H11: NM_001290049 | I11: NM_001290049chr4:76649706 | M11: =VLOOKUP(I11,错误mRNA总表!D:I,6,FALSE) -> #N/A
A12: NM_001287062.1 | B12: NC_000007.13 | C12: 66205643 | D12: 66274377 | E12: INS | F12: 2 | G12: chr7 | H12: NM_001287062 | I12: NM_001287062chr7:66205643 | M12: =VLOOKUP(I12,错误mRNA总表!D:I,6,FALSE) -> #N/A
A13: NM_001143813.1 | B13: NC_000011.9 | C13: 27676440 | D13: 27676545 | E13: DEL | F13: 1 | G13: chr11 | H13: NM_001143813 | I13: NM_001143813chr11:27676440 | M13: =VLOOKUP(I13,错误mRNA总表!D:I,6,FALSE) -> #N/A
A14: NM_001143813.1 | B14: NC_000011.9 | C14: 27676440 | D14: 27679010 | E14: DEL | F14: 1 | G14: chr11 | H14: NM_001143813 | I14: NM_001143813chr11:27676440 | M14: =VLOOKUP(I14,错误mRNA总表!D:I,6,FALSE) -> #N/A
A15: NM_001077690.1 | B15: NC_000011.9 | C15: 111652919 | D15: 111742145 | E15: DEL | F15: 1 | G15: chr11 | H15: NM_001077690 | I15: NM_001077690chr11:111652919 | J15: NM_001077690chr11:111652919 | K15: =VLOOKUP(J15,错误mRNA总表!D:J,7,FALSE) -> 纠后正确 | L15: 纠后正确 | M15: =VLOOKUP(I15,错误mRNA总表!D:I,6,FALSE) -> 0
A16: NM_024075.4 | B16: NW_003571056.1 | C16: 165232 | D16: 169309 | E16: DEL | F16: 3 | G16: NW_003571056.1 | H16: NM_024075 | I16: NM_024075:165232 | M16: =VLOOKUP(I16,错误mRNA总表!D:I,6,FALSE) -> #N/A
A17: NM_213632.2 | B17: NC_000020.10 | C17: 35757224 | D17: 35807790 | E17: INS | F17: 29 | G17: chr20 | H17: NM_213632 | I17: NM_213632chr20:35757224 | J17: NM_213632chr20:35757224 | K17: =VLOOKUP(J17,错误mRNA总表!D:J,7,FALSE) -> 纠后正确 | L17: 纠后正确 | M17: =VLOOKUP(I17,错误mRNA总表!D:I,6,FALSE) -> 0
A18: NM_001254717.1 | B18: NT_167247.1 | C18: 4760078 | D18: 4760131 | E18: INS | F18: 1 | G18: NT_167247.1 | H18: NM_001254717 | I18: NM_001254717:4760078 | M18: =VLOOKUP(I18,错误mRNA总表!D:I,6,FALSE) -> #N/A
A19: NM_153334.6 | B19: NC_000022.10 | C19: 20778874 | D19: 20779973 | E19: INS | F19: 1 | G19: chr22 | H19: NM_153334 | I19: NM_153334chr22:20778874 | M19: =VLOOKUP(I19,错误mRNA总表!D:I,6,FALSE) -> #N/A
A20: NM_153334.6 | B20: NC_000022.10 | C20: 20778874 | D20: 20780024 | E20: INS | F20: 1 | G20: chr22 | H20: NM_153334 | I20: NM_153334chr22:20778874 | M20: =VLOOKUP(I20,错误mRNA总表!D:I,6,FALSE) -> #N/A
A21: NM_153334.6 | B21: NC_000022.10 | C21: 20778874 | D21: 20780029 | E21: INS | F21: 1 | G21: chr22 | H21: NM_153334 | I21: NM_153334chr22:20778874 | M21: =VLOOKUP(I21,错误mRNA总表!D:I,6,FALSE) -> #N/A
A22: NM_001282302.1 | B22: NC_000023.10 | C22: 148685375 | D22: 148713418 | E22: INS | F22: 27 | G22: chrX | H22: NM_001282302 | I22: NM_001282302chrX:148685375 | M22: =VLOOKUP(I22,错误mRNA总表!D:I,6,FALSE) -> #N/A
A23: NM_001098534.1 | B23: NT_167245.1 | C23: 2892376 | D23: 2905672 | E23: DEL | F23: 4 | G23: NT_167245.1 | H23: NM_001098534 | I23: NM_001098534:2892376 | M23: =VLOOKUP(I23,错误mRNA总表!D:I,6,FALSE) -> #N/A
A24: NM_001304359.1 | B24: NC_000011.9 | C24: 1151580 | D24: 1162361 | E24: INS | F24: 4028 | G24: chr11 | H24: NM_001304359 | I24: NM_001304359chr11:1151580 | M24: =VLOOKUP(I24,错误mRNA总表!D:I,6,FALSE) -> #N/A
A25: NM_001304359.1 | B25: NC_000011.9 | C25: 1151580 | D25: 1162547 | E25: INS | F25: 7071 | G25: chr11 | H25: NM_001304359 | I25: NM_001304359chr11:1151580 | M25: =VLOOKUP(I25,错误mRNA总表!D:I,6,FALSE) -> #N/A
A26: NM_001304359.1 | B26: NC_000011.9 | C26: 1151580 | D26: 1212784 | E26: INS | F26: 409 | G26: chr11 | H26: NM_001304359 | I26: NM_001304359chr11:1151580 | M26: =VLOOKUP(I26,错误mRNA总表!D:I,6,FALSE) -> #N/A
A27: NM_001304359.1 | B27: NC_000011.9 | C27: 1151580 | D27: 1216317 | E27: INS | F27: 1 | G27: chr11 | H27: NM_001304359 | I27: NM_001304359chr11:1151580 | M27: =VLOOKUP(I27,错误mRNA总表!D:I,6,FALSE) -> #N/A
A28: NM_001304359.1 | B28: NC_000011.9 | C28: 1151580 | D28: 1216337 | E28: DEL | F28: 1 | G28: chr11 | H28: NM_001304359 | I28: NM_001304359chr11:1151580 | M28: =VLOOKUP(I28,错误mRNA总表!D:I,6,FALSE) -> #N/A
A29: NM_001346355.1 | B29: NC_000011.9 | C29: 46638826 | D29: 46694313 | E29: DEL | F29: 2 | G29: chr11 | H29: NM_001346355 | I29: NM_001346355chr11:46638826 | M29: =VLOOKUP(I29,错误mRNA总表!D:I,6,FALSE) -> #N/A
... A45: NR_109948.1 | B45: NW_003571036.1 | C45: 32679 | D45: 37408 | E45: DEL | F45: 3 | G45: NW_003571036.1 | H45: NR_109948 | I45: NR_109948:32679 | M45: =VLOOKUP(I45,错误mRNA总表!D:I,6,FALSE) -> #N/A
A46: NM_001113239.2 | B46: NC_000007.13 | C46: 139246316 | D46: 139316493 | E46: INS | F46: 962 | G46: chr7 | H46: NM_001113239 | I46: NM_001113239chr7:139246316 | J46: NM_001113239chr7:139246316 | K46: =VLOOKUP(J46,错误mRNA总表!D:J,7,FALSE) -> 多321个氨基酸，但rs号是多350个chr7:139257673-139316492 | L46: 多321个氨基酸，但rs号是多350个chr7:139257673-139316492 | M46: =VLOOKUP(I46,错误mRNA总表!D:I,6,FALSE) -> 0
A47: NM_001113239.2 | B47: NC_000007.13 | C47: 139246316 | D47: 139316474 | E47: INS | F47: 1 | G47: chr7 | H47: NM_001113239 | I47: NM_001113239chr7:139246316 | J47: NM_001113239chr7:139246316 | K47: =VLOOKUP(J47,错误mRNA总表!D:J,7,FALSE) -> 多321个氨基酸，但rs号是多350个chr7:139257673-139316492 | L47: 多321个氨基酸，但rs号是多350个chr7:139257673-139316492 | M47: =VLOOKUP(I47,错误mRNA总表!D:I,6,FALSE) -> 0
A48: NR_037170.1 | B48: NT_167248.1 | C48: 3381593 | D48: 3381690 | E48: INS | F48: 1 | G48: NT_167248.1 | H48: NR_037170 | I48: NR_037170:3381593 | M48: =VLOOKUP(I48,错误mRNA总表!D:I,6,FALSE) -> #N/A
A49: NM_003573.2 | B49: NC_000019.9 | C49: 41099072 | D49: 41123095 | E49: INS | F49: 1 | G49: chr19 | H49: NM_003573 | I49: NM_003573chr19:41099072 | J49: NM_003573chr19:41099072 | K49: =VLOOKUP(J49,错误mRNA总表!D:J,7,FALSE) -> 纠后正确 | L49: 纠后正确 | M49: =VLOOKUP(I49,错误mRNA总表!D:I,6,FALSE) -> 0
A50: NM_001267548.2 | B50: NC_000020.10 | C50: 62329995 | D50: 62331335 | E50: INS | F50: 1 | G50: chr20 | H50: NM_001267548 | I50: NM_001267548chr20:62329995 | M50: =VLOOKUP(I50,错误mRNA总表!D:I,6,FALSE) -> #N/A
A51: NM_001285986.1 | B51: NT_167249.1 | C51: 2467051 | D51: 2468516 | E51: DEL | F51: 6 | G51: NT_167249.1 | H51: NM_001285986 | I51: NM_001285986:2467051 | M51: =VLOOKUP(I51,错误mRNA总表!D:I,6,FALSE) -> #N/A
A52: NM_001285986.1 | B52: NT_167249.1 | C52: 2467051 | D52: 2468565 | E52: DEL | F52: 2 | G52: NT_167249.1 | H52: NM_001285986 | I52: NM_001285986:2467051 | M52: =VLOOKUP(I52,错误mRNA总表!D:I,6,FALSE) -> #N/A
A53: NM_001285986.1 | B53: NT_167249.1 | C53: 2467051 | D53: 2469065 | E53: DEL | F53: 3 | G53: NT_167249.1 | H53: NM_001285986 | I53: NM_001285986:2467051 | M53: =VLOOKUP(I53,错误mRNA总表!D:I,6,FALSE) -> #N/A
A54: NM_001285986.1 | B54: NT_167249.1 | C54: 2467051 | D54: 2469389 | E54: INS | F54: 1 | G54: NT_167249.1 | H54: NM_001285986 | I54: NM_001285986:2467051 | M54: =VLOOKUP(I54,错误mRNA总表!D:I,6,FALSE) -> #N/A
A55: NM_001285986.1 | B55: NT_167249.1 | C55: 2467051 | D55: 2469670 | E55: DEL | F55: 3 | G55: NT_167249.1 | H55: NM_001285986 | I55: NM_001285986:2467051 | M55: =VLOOKUP(I55,错误mRNA总表!D:I,6,FALSE) -> #N/A
...

Sheet 用于纠正的INDEL
A1: #mRNA | B1: Chr(NCBI) | C1: Start | D1: IndelPos(0) | E1: type | F1: Length | G1: mRNA_NoVersion | H1: Chr(use) | I1: Start(use) | J1: combin | K1: 变体是否需要纠错 | L1: 是否存在纠正信息
A2: NM_000278.3 | B2: chr10 | C2: 102505468 | D2: 102587331 | E2: DEL | F2: 3 | G2: NM_000278 | H2: chr10 | I2: 102505468 | J2: NM_000278chr10:102505468 | K2: NM_000278chr10:102505468 | L2: 纠后正确，少1个氨基酸chr10:102587349-102587376
A3: NM_000348.3 | B3: chr2 | C3: 31749656 | D3: 31805880 | E3: INS | F3: 1 | G3: NM_000348 | H3: chr2 | I3: 31749656 | J3: NM_000348chr2:31749656 | K3: NM_000348chr2:31749656 | L3: 纠后正确
A4: NM_000597.2 | B4: chr2 | C4: 217498127 | D4: 217498310 | E4: INS | F4: 9 | G4: NM_000597 | H4: chr2 | I4: 217498127 | J4: NM_000597chr2:217498127 | K4: NM_000597chr2:217498127 | L4: 无法验证，NCBIrs无此变体（rs747453609），纠后氨基酸少3个chr2:217498311-217528827
A5: NM_000615.6 | B5: chr11 | C5: 112831969 | D5: 112832308 | E5: INS | F5: 1 | G5: NM_000615 | H5: chr11 | I5: 112831969 | J5: NM_000615chr11:112831969 | K5: NM_000615chr11:112831969 | L5: 纠后正确
A6: NM_000615.6 | B6: chr11 | C6: 112831969 | D6: 112832339 | E6: DEL | F6: 1 | G6: NM_000615 | H6: chr11 | I6: 112831969 | J6: NM_000615chr11:112831969 | K6: NM_000615chr11:112831969 | L6: 纠后正确
A7: NM_000682.5 | B7: chr2 | C7: 96778623 | D7: 96780986 | E7: INS | F7: 9 | G7: NM_000682 | H7: chr2 | I7: 96778623 | J7: NM_000682chr2:96778623 | K7: NM_000682chr2:96778623 | L7: 纠后正确，少了3个氨基酸
A8: NM_000682.6 | B8: chr2 | C8: 96778623 | D8: 96780986 | E8: INS | F8: 9 | G8: NM_000682 | H8: chr2 | I8: 96778623 | J8: NM_000682chr2:96778623 | K8: NM_000682chr2:96778623 | L8: 纠后正确，少了3个氨基酸
A9: NM_000694.2 | B9: chr11 | C9: 67777790 | D9: 67786065 | E9: INS | F9: 1 | G9: NM_000694 | H9: chr11 | I9: 67777790 | J9: NM_000694chr11:67777790 | K9: NM_000694chr11:67777790 | L9: 纠后正确
A10: NM_000694.2 | B10: chr11 | C10: 67777790 | D10: 67789294 | E10: INS | F10: 1 | G10: NM_000694 | H10: chr11 | I10: 67777790 | J10: NM_000694chr11:67777790 | K10: NM_000694chr11:67777790 | L10: 纠后正确
A11: NM_000694.2 | B11: chr11 | C11: 67777790 | D11: 67795380 | E11: INS | F11: 1 | G11: NM_000694 | H11: chr11 | I11: 67777790 | J11: NM_000694chr11:67777790 | K11: NM_000694chr11:67777790 | L11: 纠后正确
A12: NM_000804.2 | B12: chr11 | C12: 71846771 | D12: 71850157 | E12: INS | F12: 2 | G12: NM_000804 | H12: chr11 | I12: 71846771 | J12: NM_000804chr11:71846771 | K12: NM_000804chr11:71846771 | L12: 纠后正确
A13: NM_001001419.1 | B13: chr5 | C13: 135468536 | D13: 135513085 | E13: INS | F13: 1 | G13: NM_001001419 | H13: chr5 | I13: 135468536 | J13: NM_001001419chr5:135468536 | K13: NM_001001419chr5:135468536 | L13: 纠后正确
... A394: XM_003959954.2 | B394: chr19 | C394: 21800852 | D394: 21821746 | E394: INS | F394: 1 | G394: XM_003959954 | H394: chr19 | I394: 21800852 | J394: XM_003959954chr19:21800852 | K394: XM_003959954chr19:21800852 | L394: 纠后正确，utr略有变化，版本不一致
A395: NM_001039127.3 | B395: chr4 | C395: 124420 | D395: 124555 | E395: INS | F395: 97 | G395: NM_001039127 | H395: chr4 | I395: 124420 | J395: NM_001039127chr4:124420 | K395: NM_001039127chr4:124420 | L395: =VLOOKUP(K395,错误mRNA总表!D:J,7,FALSE) -> 纠后区间有变化（版本不一致）与Browers相匹配，chr4:133711-136743之前有5个氨基酸不对，其他正确
A396: NM_001039127.3 | B396: chr4 | C396: 124420 | D396: 133624 | E396: DEL | F396: 2 | G396: NM_001039127 | H396: chr4 | I396: 124420 | J396: NM_001039127chr4:124420 | K396: NM_001039127chr4:124420 | L396: =VLOOKUP(K396,错误mRNA总表!D:J,7,FALSE) -> 纠后区间有变化（版本不一致）与Browers相匹配，chr4:133711-136743之前有5个氨基酸不对，其他正确
A397: NM_001039127.3 | B397: chr4 | C397: 124420 | D397: 136743 | E397: INS | F397: 91 | G397: NM_001039127 | H397: chr4 | I397: 124420 | J397: NM_001039127chr4:124420 | K397: NM_001039127chr4:124420 | L397: =VLOOKUP(K397,错误mRNA总表!D:J,7,FALSE) -> 纠后区间有变化（版本不一致）与Browers相匹配，chr4:133711-136743之前有5个氨基酸不对，其他正确
A398: NM_001039127.3 | B398: chr4 | C398: 124420 | D398: 136734 | E398: DEL | F398: 1 | G398: NM_001039127 | H398: chr4 | I398: 124420 | J398: NM_001039127chr4:124420 | K398: NM_001039127chr4:124420 | L398: =VLOOKUP(K398,错误mRNA总表!D:J,7,FALSE) -> 纠后区间有变化（版本不一致）与Browers相匹配，chr4:133711-136743之前有5个氨基酸不对，其他正确
A399: NM_001039127.5 | B399: chr4 | C399: 124358 | D399: 124555 | E399: INS | F399: 97 | G399: NM_001039127 | H399: chr4 | I399: 124358 | J399: NM_001039127chr4:124358 | K399: NM_001039127chr4:124420 | L399: =VLOOKUP(K399,错误mRNA总表!D:J,7,FALSE) -> 纠后区间有变化（版本不一致）与Browers相匹配，chr4:133711-136743之前有5个氨基酸不对，其他正确
A400: NM_001039127.5 | B400: chr4 | C400: 124358 | D400: 133634 | E400: INS | F400: 22 | G400: NM_001039127 | H400: chr4 | I400: 124358 | J400: NM_001039127chr4:124358 | K400: NM_001039127chr4:124420 | L400: =VLOOKUP(K400,错误mRNA总表!D:J,7,FALSE) -> 纠后区间有变化（版本不一致）与Browers相匹配，chr4:133711-136743之前有5个氨基酸不对，其他正确
A401: NM_001039127.5 | B401: chr4 | C401: 124358 | D401: 133624 | E401: DEL | F401: 2 | G401: NM_001039127 | H401: chr4 | I401: 124358 | J401: NM_001039127chr4:124358 | K401: NM_001039127chr4:124420 | L401: =VLOOKUP(K401,错误mRNA总表!D:J,7,FALSE) -> 纠后区间有变化（版本不一致）与Browers相匹配，chr4:133711-136743之前有5个氨基酸不对，其他正确
A402: NM_001039127.5 | B402: chr4 | C402: 124358 | D402: 137023 | E402: INS | F402: 69 | G402: NM_001039127 | H402: chr4 | I402: 124358 | J402: NM_001039127chr4:124358 | K402: NM_001039127chr4:124420 | L402: =VLOOKUP(K402,错误mRNA总表!D:J,7,FALSE) -> 纠后区间有变化（版本不一致）与Browers相匹配，chr4:133711-136743之前有5个氨基酸不对，其他正确
A403: NM_001039127.5 | B403: chr4 | C403: 124358 | D403: 137020 | E403: INS | F403: 1 | G403: NM_001039127 | H403: chr4 | I403: 124358 | J403: NM_001039127chr4:124358 | K403: NM_001039127chr4:124420 | L403: =VLOOKUP(K403,错误mRNA总表!D:J,7,FALSE) -> 纠后区间有变化（版本不一致）与Browers相匹配，chr4:133711-136743之前有5个氨基酸不对，其他正确

Sheet 最后核对情况
A1: NM_000278chr10:102505468 | B1: =VLOOKUP(A1,INDEL位置信息!J:K,2,FALSE) -> 纠后正确，少1个氨基酸chr10:102587349-102587376 | C1: NewAnnoLC/NM_000278_chr10_102505468.txt | D1: -1
A2: NM_000348chr2:31749656 | B2: =VLOOKUP(A2,INDEL位置信息!J:K,2,FALSE) -> 纠后正确 | C2: NewAnnoLC/NM_000348_chr2_31749656.txt | D2: ok
A3: NM_000597chr2:217498127 | B3: =VLOOKUP(A3,INDEL位置信息!J:K,2,FALSE) -> 无法验证，NCBIrs无此变体（rs747453609），纠后氨基酸加3个chr2:217498311-217528827 | C3: NewAnnoLC/NM_000597_chr2_217498127.txt | D3: 3
A4: NM_000615chr11:112831969 | B4: =VLOOKUP(A4,INDEL位置信息!J:K,2,FALSE) -> 纠后正确 | C4: NewAnnoLC/NM_000615_chr11_112831969.txt | D4: ok
A5: NM_000682chr2:96778623 | B5: =VLOOKUP(A5,INDEL位置信息!J:K,2,FALSE) -> 纠后正确，加了3个氨基酸 | C5: NewAnnoLC/NM_000682_chr2_96778623.txt | D5: 3
A6: NM_000694chr11:67777790 | B6: =VLOOKUP(A6,INDEL位置信息!J:K,2,FALSE) -> 纠后正确 | C6: NewAnnoLC/NM_000694_chr11_67777790.txt | D6: ok
A7: NM_000804chr11:71846771 | B7: =VLOOKUP(A7,INDEL位置信息!J:K,2,FALSE) -> 纠后正确 | C7: NewAnnoLC/NM_000804_chr11_71846771.txt | D7: ok
A8: NM_001001419chr5:135468536 | B8: =VLOOKUP(A8,INDEL位置信息!J:K,2,FALSE) -> 纠后正确 | C8: NewAnnoLC/NM_001001419_chr5_135468536.txt | D8: ok
A9: NM_001001420chr5:135468536 | B9: =VLOOKUP(A9,INDEL位置信息!J:K,2,FALSE) -> 纠后正确 | C9: NewAnnoLC/NM_001001420_chr5_135468536.txt | D9: ok
A10: NM_001001520chr19:4472255 | B10: =VLOOKUP(A10,INDEL位置信息!J:K,2,FALSE) -> 纠后正确，且氨基酸少5个chr19：4499665-4502022 | C10: NewAnnoLC/NM_001001520_chr19_4472255.txt | D10: -5
A11: NM_001002836chr19:56598732 | B11: =VLOOKUP(A11,INDEL位置信息!J:K,2,FALSE) -> 纠后正确，少1个氨基酸chr19:56599389-56599751 | C11: NewAnnoLC/NM_001002836_chr19_56598732.txt | D11: -1
A12: NM_001005861chr3:133875978 | B12: =VLOOKUP(A12,INDEL位置信息!J:K,2,FALSE) -> 纠后正确 | C12: NewAnnoLC/NM_001005861_chr3_133875978.txt | D12: ok
A13: NM_001005914chr3:50305040 | B13: =VLOOKUP(A13,INDEL位置信息!J:K,2,FALSE) -> 纠后正确 | C13: NewAnnoLC/NM_001005914_chr3_50305040.txt | D13: ok
A14: NM_001007277chr11:125439298 | B14: =VLOOKUP(A14,INDEL位置信息!J:K,2,FALSE) -> 纠后正确 | C14: NewAnnoLC/NM_001007277_chr11_125439298.txt | D14: ok
A15: NM_001008239chr18:43753988 | B15: =VLOOKUP(A15,INDEL位置信息!J:K,2,FALSE) -> 纠后正确，且氨基酸加1个chr18：43833705-43843081 | C15: NewAnnoLC/NM_001008239_chr18_43753988.txt | D15: 1
A16: NM_001008401chr19:53935227 | B16: =VLOOKUP(A16,INDEL位置信息!J:K,2,FALSE) -> 纠后正确 | C16: NewAnnoLC/NM_001008401_chr19_53935227.txt | D16: ok
A17: NM_001010855chr17:8706055 | B17: =VLOOKUP(A17,INDEL位置信息!J:K,2,FALSE) -> 纠后正确 | C17: NewAnnoLC/NM_001010855_chr17_8706055.txt | D17: ok
A18: NM_001012288chrX:1314869 | B18: =VLOOKUP(A18,INDEL位置信息!J:K,2,FALSE) -> 无rs号验证，氨基酸加1个chrX:1314875-1314998 | C18: NewAnnoLC/NM_001012288_chrX_1314869.txt | D18: 1
A19: NM_001012288chrY:1264869 | B19: =VLOOKUP(A19,INDEL位置信息!I:K,3,FALSE) -> 无rs号验证，氨基酸加1个chrX:1314875-1314998 | C19: NewAnnoLC/NM_001012288_chrY_1264869.txt | D19: 1
A20: NM_001012709chr11:1642188 | B20: =VLOOKUP(A20,INDEL位置信息!J:K,2,FALSE) -> 纠后正确,加60个氨基酸chr11:1642637-1642939 | C20: NewAnnoLC/NM_001012709_chr11_1642188.txt | D20: 60
A21: NM_001013742chrX:50111879 | B21: =VLOOKUP(A21,INDEL位置信息!J:K,2,FALSE) -> 纠后正确 | C21: NewAnnoLC/NM_001013742_chrX_50111879.txt | D21: ok
A22: NM_001017396chr2:95831183 | B22: =VLOOKUP(A22,INDEL位置信息!J:K,2,FALSE) -> 纠后正确，氨基酸少1个，chr2：95847047-95847854 | C22: NewAnnoLC/NM_001017396_chr2_95831183.txt | D22: -1
A23: NM_001023560chr6:28234788 | B23: =VLOOKUP(A23,INDEL位置信息!J:K,2,FALSE) -> 纠后正确 | C23: NewAnnoLC/NM_001023560_chr6_28234788.txt | D23: ok
A24: NM_001030010chr11:67777790 | B24: =VLOOKUP(A24,INDEL位置信息!J:K,2,FALSE) -> 纠后正确 | C24: NewAnnoLC/NM_001030010_chr11_67777790.txt | D24: ok
A25: NM_001037954chr11:111807927 | B25: =VLOOKUP(A25,INDEL位置信息!J:K,2,FALSE) -> 纠后正确，utr略有变化，版本不一致 | C25: NewAnnoLC/NM_001037954_chr11_111807927.txt | D25: ok
A26: NM_001039127chr4:124420 | B26: 纠后区间有变化（版本不一致）与Browers相匹配，chr4:154702之前的与rs号信息不一致，之后一致 | C26: NewAnnoLC/NM_001039127_chr4_124420.txt | D26: ok
A27: NM_001039350chr7:153584419 | B27: =VLOOKUP(A27,INDEL位置信息!J:K,2,FALSE) -> 纠后正确 | C27: NewAnnoLC/NM_001039350_chr7_153584419.txt | D27: ok
A28: NM_001039476chr16:135800 | B28: =VLOOKUP(A28,INDEL位置信息!J:K,2,FALSE) -> 纠后正确 | C28: NewAnnoLC/NM_001039476_chr16_135800.txt | D28: ok
A29: NM_001039887chr19:36249044 | B29: =VLOOKUP(A29,INDEL位置信息!J:K,2,FALSE) -> 纠后正确 | C29: NewAnnoLC/NM_001039887_chr19_36249044.txt | D29: ok
A30: NM_001042544chr19:41103141 | B30: =VLOOKUP(A30,INDEL位置信息!J:K,2,FALSE) -> 纠后正确 | C30: NewAnnoLC/NM_001042544_chr19_41103141.txt | D30: ok
A31: NM_001042545chr19:41107277 | B31: =VLOOKUP(A31,INDEL位置信息!J:K,2,FALSE) -> 纠后正确 | C31: NewAnnoLC/NM_001042545_chr19_41107277.txt | D31: ok
A32: NM_001048201chr19:4909510 | B32: =VLOOKUP(A32,INDEL位置信息!J:K,2,FALSE) -> 纠后正确 | C32: NewAnnoLC/NM_001048201_chr19_4909510.txt | D32: ok
A33: NM_001048205chr14:24641234 | B33: =VLOOKUP(A33,INDEL位置信息!J:K,2,FALSE) -> 纠后正确，加1个氨基酸chr14:24646414-24649301 | C33: NewAnnoLC/NM_001048205_chr14_24641234.txt | D33: 1
A34: NM_001076682chr11:112831969 | B34: =VLOOKUP(A34,INDEL位置信息!J:K,2,FALSE) -> 纠后正确 | C34: NewAnnoLC/NM_001076682_chr11_112831969.txt | D34: ok
A35: NM_001077238chr19:2328629 | B35: =VLOOKUP(A35,INDEL位置信息!J:K,2,FALSE) -> 纠后正确 | C35: NewAnnoLC/NM_001077238_chr19_2328629.txt | D35: ok
A36: NM_001077350chr16:135800 | B36: =VLOOKUP(A36,INDEL位置信息!J:K,2,FALSE) -> 纠后正确 | C36: NewAnnoLC/NM_001077350_chr16_135800.txt | D36: ok
A37: NM_001077527chr8:143738874 | B37: =VLOOKUP(A37,INDEL位置信息!J:K,2,FALSE) -> 纠后正确，版本不一致，utr略有变化 | C37: NewAnnoLC/NM_001077527_chr8_143738874.txt | D37: ok
A38: NM_001077690chr11:111652919 | B38: =VLOOKUP(A38,INDEL位置信息!J:K,2,FALSE) -> 纠后正确 | C38: NewAnnoLC/NM_001077690_chr11_111652919.txt | D38: ok
A39: NM_001080423chr3:14530619 | B39: =VLOOKUP(A39,INDEL位置信息!J:K,2,FALSE) -> 纠后正确 | C39: NewAnnoLC/NM_001080423_chr3_14530619.txt | D39: ok
A40: NM_001080519chr17:79373540 | B40: =VLOOKUP(A40,INDEL位置信息!J:K,2,FALSE) -> 纠后正确,区间略有变化，加57个氨基酸chr8:79394663-79433358 | C40: NewAnnoLC/NM_001080519_chr17_79373540.txt | D40: 57
...

Sheet 区间变化核对
A1: NM_001080519.2 | B1: New | C1: 79373539 | D1: 79394661 | E1: 79405393 | F1: 79408856 | G1: 79410834 | H1: 79411406 | I1: 79411693 | J1: 79412040 | K1: 79412379 | L1: 79414061 | M1: 79418693 | N1: 79418996 | O1: 79419748 | P1: 79422292 | Q1: 79423322 | R1: 79424439 | S1: 79425190 | T1: 79425646 | U1: 79425838 | V1: 79426079 | W1: 79426278 | X1: 79426521 | Y1: 79427302 | Z1: 79427555 | AA1: 79427891 | AB1: 79429765 | AC1: 79430636
C2: 79373717 | D2: 79394672 | E2: 79405518 | F2: 79410590 | G2: 79410943 | H2: 79411594 | I2: 79411852 | J2: 79412204 | K2: 79412707 | L2: 79414874 | M2: 79418896 | N2: 79419133 | O2: 79419877 | P2: 79422416 | Q2: 79423615 | R2: 79424618 | S2: 79425492 | T2: 79425751 | U2: 79425995 | V2: 79426194 | W2: 79426354 | X2: 79426630 | Y2: 79427422 | Z2: 79427732 | AA2: 79429072 | AB2: 79430002 | AC2: 79433358
C3: rs782567217 | D3: 79373730 | E3: c.178+13C>T | F3: rs781826535 | G3: 79394685 | H3: c.281+13T>G | I3: rs781928879 | J3: 79405391 | K3: c.357-3T>C
A4: NM_001080519.2 | B4: Raw | C4: 79373539 | D4: 79394661 | E4: 79405394 | F4: 79408856 | G4: 79410834 | H4: 79411406 | I4: 79411693 | J4: 79412040 | K4: 79412379 | L4: 79414061 | M4: 79418693 | N4: 79418996 | O4: 79419748 | P4: 79422292 | Q4: 79423322 | R4: 79424439 | S4: 79425190 | T4: 79425646 | U4: 79425838 | V4: 79426079 | W4: 79426278 | X4: 79426521 | Y4: 79427302 | Z4: 79427555 | AA4: 79427891 | AB4: 79429765 | AC4: 79430636
C5: 79373716 | D5: 79394670 | E5: 79405518 | F5: 79410590 | G5: 79410943 | H5: 79411594 | I5: 79411852 | J5: 79412204 | K5: 79412707 | L5: 79414874 | M5: 79418896 | N5: 79419133 | O5: 79419877 | P5: 79422416 | Q5: 79423615 | R5: 79424618 | S5: 79425492 | T5: 79425751 | U5: 79425995 | V5: 79426194 | W5: 79426354 | X5: 79426630 | Y5: 79427422 | Z5: 79427732 | AA5: 79429072 | AB5: 79430002 | AC5: 79433358
C6: =IF(C4=C1,1,0) -> 1 | D6: =IF(D4=D1,1,0) -> 1 | E6: =IF(E4=E1,1,0) -> 0 | F6: =IF(F4=F1,1,0) -> 1 | G6: =IF(G4=G1,1,0) -> 1 | H6: =IF(H4=H1,1,0) -> 1 | I6: =IF(I4=I1,1,0) -> 1 | J6: =IF(J4=J1,1,0) -> 1 | ... AC6: =IF(AC4=AC1,1,0) -> 1
C7: =IF(C5=C2,1,0) -> 0 | D7: =IF(D5=D2,1,0) -> 0 | E7: =IF(E5=E2,1,0) -> 1 | F7: =IF(F5=F2,1,0) -> 1 | G7: =IF(G5=G2,1,0) -> 1 | H7: =IF(H5=H2,1,0) -> 1 | I7: =IF(I5=I2,1,0) -> 1 | J7: =IF(J5=J2,1,0) -> 1 | ... AC7: =IF(AC5=AC2,1,0) -> 1
A9: NM_003715.2 | B9: New | C9: 76649828 | D9: 76657489 | E9: 76676614 | F9: 76678648 | G9: 76691591 | H9: 76691974 | I9: 76692234 | J9: 76695828 | K9: 76703832 | L9: 76708214 | M9: 76711302 | N9: 76711795 | O9: 76714842 | P9: 76720774 | Q9: 76721503 | R9: 76721770 | S9: 76722231 | T9: 76725286 | U9: 76726292 | V9: 76727638 | W9: 76730105 | X9: 76731584 | Y9: 76733312 | Z9: 76734358
C10: 76650069 | D10: 76657500 | E10: 76676635 | F10: 76678726 | G10: 76691692 | H10: 76692077 | I10: 76692290 | J10: 76695949 | K10: 76704011 | L10: 76708355 | M10: 76711391 | N10: 76711950 | O10: 76715054 | P10: 76720885 | Q10: 76721622 | R10: 76721952 | S10: 76722353 | T10: 76725425 | U10: 76726456 | V10: 76727725 | W10: 76730204 | X10: 76731692 | Y10: 76733528 | Z10: 76735366
C11: rs565335012 | D11: 76657471 | E11: c.90-19G>A | F11: rs6813480 | G11: 76657504 | H11: c.100+4T>C | I11: rs760475866 | J11: 76676608 | K11: c.197-7T>G
A12: NM_003715.2 | B12: Raw | C12: 76649828 | D12: 76657490 | E12: 76676616 | F12: 76678648 | G12: 76691591 | H12: 76691974 | I12: 76692234 | J12: 76695828 | K12: 76703832 | L12: 76708214 | M12: 76711302 | N12: 76711795 | O12: 76714842 | P12: 76720774 | Q12: 76721503 | R12: 76721770 | S12: 76722231 | T12: 76725286 | U12: 76726292 | V12: 76727638 | W12: 76730105 | X12: 76731584 | Y12: 76733312 | Z12: 76734358
C13: 76650069 | D13: 76657499 | E13: 76676635 | F13: 76678726 | G13: 76691692 | H13: 76692077 | I13: 76692290 | J13: 76695949 | K13: 76704011 | L13: 76708355 | M13: 76711391 | N13: 76711950 | O13: 76715054 | P13: 76720885 | Q13: 76721622 | R13: 76721952 | S13: 76722353 | T13: 76725425 | U13: 76726456 | V13: 76727725 | W13: 76730204 | X13: 76731692 | Y13: 76733528 | Z13: 76735366
C14: =IF(C12=C9,1,0) -> 1 | D14: =IF(D12=D9,1,0) -> 0 | E14: =IF(E12=E9,1,0) -> 0 | F14: =IF(F12=F9,1,0) -> 1 | G14: =IF(G12=G9,1,0) -> 1 | H14: =IF(H12=H9,1,0) -> 1 | I14: =IF(I12=I9,1,0) -> 1 | J14: =IF(J12=J9,1,0) -> 1 | ... Z14: =IF(Z12=Z9,1,0) -> 1
C15: =IF(C13=C10,1,0) -> 1 | D15: =IF(D13=D10,1,0) -> 0 | E15: =IF(E13=E10,1,0) -> 1 | F15: =IF(F13=F10,1,0) -> 1 | G15: =IF(G13=G10,1,0) -> 1 | H15: =IF(H13=H10,1,0) -> 1 | I15: =IF(I13=I10,1,0) -> 1 | J15: =IF(J13=J10,1,0) -> 1 | ... Z15: =IF(Z13=Z10,1,0) -> 1
A17: NM_012133 | C17: 130146078 | D17: 130147114 | E17: 130147525 | F17: 130148402 | G17: 130152303 | H17: 130153697 | I17: 130255187 | J17: 130269204 | K17: 130273720 | L17: 130277153 | M17: 130287346 | N17: 130295823 | O17: 130297022 | P17: 130298414 | Q17: 130301860 | R17: 130337708 | S17: 130347806 | T17: 130351688 | U17: 130352321 | V17: 130353471
C18: 130146647 | D18: 130147213 | E18: 130147664 | F18: 130148522 | G18: 130152328 | H18: 130153718 | I18: 130255198 | J18: 130269215 | K18: 130273732 | L18: 130277168 | M18: 130287359 | N18: 130295981 | O18: 130297109 | P18: 130298507 | Q18: 130301936 | R18: 130337788 | S18: 130347878 | T18: 130351769 | U18: 130352374 | V18: 130353598
E19: rs782074020 | F19: 130148523 | G19: c.2150-23G>C | I19: 与rs号差异较大，氨基酸位置可能不正确
C20: 130146078 | D20: 130147114 | E20: 130147525 | F20: 130148402 | G20: 130152303 | H20: 130153697 | I20: 130255187 | J20: 130269204 | K20: 130273722 | L20: 130277153 | M20: 130287348 | N20: 130295825 | O20: 130297022 | P20: 130298414 | Q20: 130301860 | R20: 130337708 | S20: 130347806 | T20: 130351688 | U20: 130352321 | V20: 130353471
C21: 130146647 | D21: 130147213 | E21: 130147664 | F21: 130148520 | G21: 130152328 | H21: 130153718 | I21: 130255196 | J21: 130269213 | K21: 130273731 | L21: 130277166 | M21: 130287357 | N21: 130295981 | O21: 130297109 | P21: 130298507 | Q21: 130301936 | R21: 130337788 | S21: 130347878 | T21: 130351769 | U21: 130352374 | V21: 130353598
C22: =IF(C17=C20,1,0) -> 1 | D22: =IF(D17=D20,1,0) -> 1 | E22: =IF(E17=E20,1,0) -> 1 | F22: =IF(F17=F20,1,0) -> 1 | G22: =IF(G17=G20,1,0) -> 1 | H22: =IF(H17=H20,1,0) -> 1 | I22: =IF(I17=I20,1,0) -> 1 | J22: =IF(J17=J20,1,0) -> 1 | ... V22: =IF(V17=V20,1,0) -> 1
C23: =IF(C18=C21,1,0) -> 1 | D23: =IF(D18=D21,1,0) -> 1 | E23: =IF(E18=E21,1,0) -> 1 | F23: =IF(F18=F21,1,0) -> 0 | G23: =IF(G18=G21,1,0) -> 1 | H23: =IF(H18=H21,1,0) -> 1 | I23: =IF(I18=I21,1,0) -> 0 | J23: =IF(J18=J21,1,0) -> 0 | ... V23: =IF(V18=V21,1,0) -> 1
A25: NM_012309 | B25: New | C25: 70313960 | D25: 70331418 | E25: 70335432 | F25: 70336380 | G25: 70338439 | H25: 70346674 | I25: 70348027 | J25: 70348310 | K25: 70348900 | L25: 70505932 | M25: 70507700 | N25: 70544792 | O25: 70644547 | P25: 70653106 | Q25: 70666468 | R25: 70742605 | S25: 70766133 | T25: 70776123 | U25: 70785648 | V25: 70803467 | W25: 70805582 | X25: 70820986 | Y25: 70824338 | Z25: 70829874 | AA25: 70858165 | AB25: 70935742
C26: 70319544 | D26: 70333825 | E26: 70335453 | F26: 70336492 | G26: 70338570 | H26: 70346695 | I26: 70348036 | J26: 70348391 | K26: 70349036 | L26: 70506057 | M26: 70507783 | N26: 70544868 | O26: 70644661 | P26: 70653276 | Q26: 70666787 | R26: 70742678 | S26: 70766144 | T26: 70776150 | U26: 70785659 | V26: 70803635 | W26: 70805734 | X26: 70821095 | Y26: 70824410 | Z26: 70830078 | AA26: 70858384 | AB26: 70935808
S27: 70766127 | T27: c.1108-23455G>C | U27: 与rs号差异较大，氨基酸位置可能不正确
B28: Raw | C28: 70313960 | D28: 70331418 | E28: 70335432 | F28: 70336380 | G28: 70338439 | H28: 70346674 | I28: 70348027 | J28: 70348310 | K28: 70348900 | L28: 70505932 | M28: 70507700 | N28: 70544792 | O28: 70644547 | P28: 70653106 | Q28: 70666468 | R28: 70742605 | S28: 70766135 | T28: 70776125 | U28: 70785648 | V28: 70803467 | W28: 70805582 | X28: 70820986 | Y28: 70824338 | Z28: 70829874 | AA28: 70858165 | AB28: 70935742
C29: 70319544 | D29: 70333825 | E29: 70335453 | F29: 70336492 | G29: 70338570 | H29: 70346695 | I29: 70348036 | J29: 70348391 | K29: 70349036 | L29: 70506057 | M29: 70507783 | N29: 70544868 | O29: 70644661 | P29: 70653276 | Q29: 70666787 | R29: 70742678 | S29: 70766144 | T29: 70776150 | U29: 70785657 | V29: 70803635 | W29: 70805734 | X29: 70821095 | Y29: 70824410 | Z29: 70830078 | AA29: 70858384 | AB29: 70935808
C30: =IF(C25=C28,1,0) -> 1 | D30: =IF(D25=D28,1,0) -> 1 | E30: =IF(E25=E28,1,0) -> 1 | F30: =IF(F25=F28,1,0) -> 1 | G30: =IF(G25=G28,1,0) -> 1 | H30: =IF(H25=H28,1,0) -> 1 | I30: =IF(I25=I28,1,0) -> 1 | J30: =IF(J25=J28,1,0) -> 1 | ... AB30: =IF(AB25=AB28,1,0) -> 1
C31: =IF(C26=C29,1,0) -> 1 | D31: =IF(D26=D29,1,0) -> 1 | E31: =IF(E26=E29,1,0) -> 1 | F31: =IF(F26=F29,1,0) -> 1 | G31: =IF(G26=G29,1,0) -> 1 | H31: =IF(H26=H29,1,0) -> 1 | I31: =IF(I26=I29,1,0) -> 1 | J31: =IF(J26=J29,1,0) -> 1 | ... AB31: =IF(AB26=AB29,1,0) -> 1
A33: NM_017940.3 | B33: New | C33: 16890411 | D33: 16891301 | E33: 16892127 | F33: 16893674 | G33: 16894473 | H33: 16895567 | I33: 16899636 | J33: 16900981 | K33: 16901651 | L33: 16902761 | M33: 16903811 | N33: 16905687 | O33: 16907239 | P33: 16907914 | Q33: 16909038 | R33: 16910088 | S33: 16911983 | T33: 16913544 | U33: 16914219 | V33: 16915343 | W33: 16916393 | X33: 16918341 | Y33: 16918653 | Z33: 16919935 | AA33: 16921086 | AB33: 16921425 | AC33: 16935002 | AD33: 16939832
C34: 16890681 | D34: 16891413 | E34: 16892302 | F34: 16893846 | G34: 16894525 | H34: 16895731 | I34: 16899688 | J34: 16901187 | K34: 16901724 | L34: 16902976 | M34: 16903914 | N34: 16905897 | O34: 16907451 | P34: 16907987 | Q34: 16909253 | R34: 16910191 | S34: 16912193 | T34: 16913756 | U34: 16914292 | V34: 16915558 | W34: 16916496 | X34: 16918551 | Y34: 16918808 | Z34: 16920062 | AA34: 16921156 | AB34: 16921504 | AC34: 16935274 | AD34: 16939982
D35: 无法验证
A36: NM_017940.3 | B36: Raw | C36: 16888921 | D36: 16891301 | E36: 16892127 | F36: 16893673 | G36: 16894473 | H36: 16895567 | I36: 16899636 | J36: 16900981 | K36: 16901651 | L36: 16902761 | M36: 16903811 | N36: 16905687 | O36: 16907239 | P36: 16907914 | Q36: 16909038 | R36: 16910088 | S36: 16911983 | T36: 16913544 | U36: 16914219 | V36: 16915343 | W36: 16916393 | X36: 16918341 | Y36: 16918653 | Z36: 16919935 | AA36: 16921086 | AB36: 16921425 | AC36: 16935002 | AD36: 16939832
C37: 16890681 | D37: 16891413 | E37: 16892304 | F37: 16893846 | G37: 16894525 | H37: 16895731 | I37: 16899688 | J37: 16901187 | K37: 16901724 | L37: 16902976 | M37: 16903914 | N37: 16905897 | O37: 16907451 | P37: 16907987 | Q37: 16909253 | R37: 16910191 | S37: 16912193 | T37: 16913756 | U37: 16914292 | V37: 16915558 | W37: 16916496 | X37: 16918551 | Y37: 16918808 | Z37: 16920062 | AA37: 16921156 | AB37: 16921504 | AC37: 16935274 | AD37: 16940100
C38: =IF(C33=C36,1,0) -> 0 | D38: =IF(D33=D36,1,0) -> 1 | E38: =IF(E33=E36,1,0) -> 1 | F38: =IF(F33=F36,1,0) -> 0 | G38: =IF(G33=G36,1,0) -> 1 | H38: =IF(H33=H36,1,0) -> 1 | I38: =IF(I33=I36,1,0) -> 1 | J38: =IF(J33=J36,1,0) -> 1 | ... AD38: =IF(AD33=AD36,1,0) -> 1
C39: =IF(C34=C37,1,0) -> 1 | D39: =IF(D34=D37,1,0) -> 1 | E39: =IF(E34=E37,1,0) -> 0 | F39: =IF(F34=F37,1,0) -> 1 | G39: =IF(G34=G37,1,0) -> 1 | H39: =IF(H34=H37,1,0) -> 1 | I39: =IF(I34=I37,1,0) -> 1 | J39: =IF(J34=J37,1,0) -> 1 | ... AD39: =IF(AD34=AD37,1,0) -> 0
A41: NM_031308 | B41: New | C41: 144939491 | D41: 144940300 | E41: 144952605
C42: 144940300 | D42: 144947466 | E42: 144952632
D43: rs375286281 | E43: 144952607 | F43: c.-47A>G
B44: Raw | C44: 144939911 | D44: 144940566
C45: 144940566 | D45: 144947434
...

Sheet 染色体对应
A1: NC_000001.10 | B1: chr1
A2: NC_000002.11 | B2: chr2
A3: NC_000003.11 | B3: chr3
A4: NC_000004.11 | B4: chr4
A5: NC_000005.9 | B5: chr5
A6: NC_000006.11 | B6: chr6
A7: NC_000007.13 | B7: chr7
A8: NC_000008.10 | B8: chr8
A9: NC_000009.11 | B9: chr9
A10: NC_000010.10 | B10: chr10
A11: NC_000011.9 | B11: chr11
A12: NC_000012.11 | B12: chr12
... A24: NC_000024.9 | B24: chrY

Sheet Sheet3
A1: NM_000104 | B1: chr2 | C1: 38294745 | D1: NM_000104chr2:38294746 | E1: 无变化
A2: NM_000158 | B2: chr3 | C2: 81538849 | D2: NM_000158chr3:81538850 | E2: 无变化
A3: NM_000278 | B3: chr10 | C3: 102505467 | D3: NM_000278chr10:102505468 | E3: 整体少1个氨基酸chr10:102587349-102587376
A4: NM_000348 | B4: chr2 | C4: 31749655 | D4: NM_000348chr2:31749656 | E4: 纠后正确
A5: NM_000442 | B5: chr17 | C5: 62396774 | D5: NM_000442chr17:62396775 | E5: 纠后不正确，在62404846DEL1
A6: NM_000544 | B6: chr6 | C6: 32793186 | D6: NM_000544chr6:32793187 | E6: 无变化
A7: NM_000597 | B7: chr2 | C7: 217498126 | D7: NM_000597chr2:217498127 | E7: 氨基酸整体少3个chr2:217498311-217528827
A8: NM_000615 | B8: chr11 | C8: 112831968 | D8: NM_000615chr11:112831969 | E8: 纠后正确
A9: NM_000682 | B9: chr2 | C9: 96778622 | D9: NM_000682chr2:96778623 | E9: 无变化
A10: NM_000694 | B10: chr11 | C10: 67777789 | D10: NM_000694chr11:67777790 | E10: 纠后正确
A11: NM_000804 | B11: chr11 | C11: 71846770 | D11: NM_000804chr11:71846771 | E11: 纠后正确
A12: NM_000828 | B12: chrX | C12: 122318095 | D12: NM_000828chrX:122318096 | E12: 无变化
... A199: NM_033401 | B199: chr16 | C199: 76311175 | D199: NM_033401chr16:76311176 | E199: 纠后正确
A200: NM_052886 | B200: chr8 | C200: 120220609 | D200: NM_052886chr8:120220610 | E200: 纠后正确 | G200: INPP5D | I200: NBPF9
A201: NM_052892 | B201: chr16 | C201: 81134483 | D201: NM_052892chr16:81134484 | E201: 纠后正确 | G201: SRGAP2 | I201: MILR1
A202: NM_080669 | B202: chr17 | C202: 26721660 | D202: NM_080669chr17:26721661 | E202: 纠后正确 | G202: ECSCR | I202: LYPD8
A203: NM_130445 | B203: chr21 | C203: 46825096 | D203: NM_130445chr21:46825097 | E203: 整体少3个氨基酸chr21:46924440-46932312 | G203: SH3RF3 | I203: PLCL2
A204: NM_130464 | B204: chr16 | C204: 21413454 | D204: NM_130464chr16:21413455 | E204: 纠后正确 | G204: IKZF1 | I204: TMEM114
A205: NM_130797 | B205: chr7 | C205: 153749776 | D205: NM_130797chr7:153749777 | E205: 纠后正确？ | G205: C1R | I205: SRGAP2
A206: NM_130797 | B206: chr7 | C206: 154429530 | D206: NM_130797chr7:154429531 | E206: 原来正确 | G206: KIF5C | I206: SYN2
A207: NM_133373 | B207: chr17 | C207: 43189007 | D207: NM_133373chr17:43189008 | E207: 纠后正确 | G207: MLXIP | I207: FGF16
A208: NM_138319 | B208: chr15 | C208: 101844132 | D208: NM_138319chr15:101844133 | E208: 无变化 | I208: GTPBP6
A209: NM_138320 | B209: chr15 | C209: 101853221 | D209: NM_138320chr15:101853222 | E209: 无变化 | I209: PPP2R2D
A210: NM_138321 | B210: chr15 | C210: 101853221 | D210: NM_138321chr15:101853222 | E210: 无变化 | I210: MOB2
A211: NM_138322 | B211: chr15 | C211: 101923952 | D211: NM_138322chr15:101923953 | E211: 无变化 | I211: FAM101B
A212: NM_138323 | B212: chr15 | C212: 101886946 | D212: NM_138323chr15:101886947 | E212: 无变化 | I212: FOXO6
A213: NM_138324 | B213: chr15 | C213: 101886946 | D213: NM_138324chr15:101886947 | E213: 无变化 | I213: OFCC1
A214: NM_138325 | B214: chr15 | C214: 101905078 | D214: NM_138325chr15:101905079 | E214: 无变化
A215: NM_138352 | B215: chr19 | C215: 14199228 | D215: NM_138352chr19:14199229 | E215: 原来正确
A216: NM_145055 | B216: chr18 | C216: 43753987 | D216: NM_145055chr18:43753988 | E216: 氨基酸整体少1个chr18：43833705-43843081
A217: NM_145171 | B217: chr14 | C217: 63779548 | D217: NM_145171chr14:63779549 | E217: 纠后正确
A218: NM_145660 | B218: chr22 | C218: 36585175 | D218: NM_145660chr22:36585176 | E218: 无变化
A219: NM_145728 | B219: chr15 | C219: 99645285 | D219: NM_145728chr15:99645286 | E219: 纠后正确
A220: NM_152338 | B220: chr16 | C220: 29789560 | D220: NM_152338chr16:29789561 | E220: 无变化
A221: NM_152914 | B221: chr17 | C221: 21142182 | D221: NM_152914chr17:21142183 | E221: 纠后正确
A222: NM_152988 | B222: chr19 | C222: 2328628 | D222: NM_152988chr19:2328629 | E222: 纠后正确
A223: NM_173059 | B223: chr7 | C223: 100331248 | D223: NM_173059chr7:100331249 | E223: 纠后正确
A224: NM_173681 | B224: chr7 | C224: 150709296 | D224: NM_173681chr7:150709297 | E224: 纠后正确
A225: NM_175862 | B225: chr3 | C225: 121774208 | D225: NM_175862chr3:121774209 | E225: 无变化
... A241: NM_207421 | B241: chr1 | C241: 17698740 | D241: NM_207421chr1:17698741 | E241: 纠后正确

Sheet Sheet2
A1: 总mRNA | B1: 存在错误mRNA | C1: cds为3的倍数（AA=1） | D1: cds为3的倍数（AA=2） | E1: cds为3的倍数（AA=3） | F1: cds为3的倍数（AA=4） | G1: cds为3的倍数（AA=5） | H1: cds为3的倍数（AA=6） | I1: cds为3的倍数（AA=7） | J1: cds为3的倍数（AA=8） | K1: cds为3的倍数（AA=9） | L1: cds为3的倍数（AA=10） | M1: cds为3的倍数（AA>10） | N1: cds不为3的倍数（AA<=10） | O1: cds不为3的倍数（AA>10）
A2: 34040 | B2: 1337（774） | C2: 915（517） | D2: 79（48） | E2: 8（3） | F2: 2（2） | G2: 2（2,同基因名XY） | H2: 5（2，DPP6有两个位置3个mRNA） | I2: 0 | J2: 0 | K2: 2（1） | L2: 6（2,INPP5D有两个位置2个mRNA） | M2: 72（54） | N2: 11（7, 含1个编码正确） | O2: 235（154）
A3: 第一次修正数目 | G3: 2(1) | H3: 2(1,DPP6) | K3: 2(1) | L3: 4(1) | M3: 43(31) | N3: 2(1) | O3: 161(109)
A4: 第二次修正数目 | M4: 14(10) | O4: 10(9)
A5: 第三次修正数目
A6: 基因分为多段(暂不解决) | H6: 1(1,DPP6) | L6: 2(1) | M6: 5(3) | N6: 1(1,编码正确) | O6: 28（8）
A7: 基因不完整(CDS起始终止变化) | M7: 7(6) | N7: 3(2) | O7: 16(14)
A8: 变体或基因被取消、假基因 | M8: 1（1） | N8: 3（1） | O8: 14（14）
A9: 未解决 | M9: 2（1） | N9: 2（1） | O9: 6（3）
B12: 总mRNA | C12: 存在差异mRNA | D12: 氨基酸差异<=10 | E12: 氨基酸差异>=10
B13: 34042（19477） | C13: 1337（774） | D13: 1030(574) | E13: 307(207)
A14: 多段基因 | D14: 6（3） | E14: 37(12)
A15: 基因不完整 | D15: 3（2） | E15: 23（21）
A16: 变体或基因被取消 | D16: 3（1） | E16: 14（14）
A17: 修正数目 | D17: 12（5） | E17: 228（157）
D26: DNAH11
D27: NEK3
D28: LOC100996372
D29: LOC100996392
D30: LOC100996428
D31: LOC730058
D32: LOC100996432
D33: LOC100996350
D34: LOC100996575
D35: LOC100996885
D36: LOC101060037
D37: SRGAP3-AS3
... D39: GOLGA6L10
H166: ZNF595 | K166: ARHGEF25 | L166: TTC25
H167: SSPO | K167: ENTPD6 | L167: TSPAN10
H168: KRTAP10-7 | K168: KLRD1 | L168: SRSF8
H169: XKR5 | K169: AP1B1 | L169: KRBA1
H170: PADI6 | K170: CEP55 | L170: PPP1R9B
H171: AGAP10 | K171: PAN2 | L171: ORAI1
H172: ZNF852 | K172: RWDD3 | L172: HSH2D
H173: 61E3.4 | K173: UGT8 | L173: MUC13
H174: MUC19 | K174: WDSUB1 | L174: ZCCHC3
H175: LOC400682 | K175: SLC39A13 | L175: CNTNAP4
K176: SPON2 | L176: CDK11B
K177: GBA3 | L177: SHANK3
...
